Workbook

Sheet Synthèse
A1: Récapitulatif des requis — VISU PTBG 2.2.0
A2: Spécification NCS/00/I/COMMON----/ES/010 Rev. A (13/10/2026) — relecture : Sébastien Kubasik — état au 28/10/2026
A4: Statut | B4: Lignes de requis | C4: Part
A5: Implémenté et testé | B5: =COUNTIF(Requis!$J:$J,A5) -> 49 | C5: =IF($B$9=0,0,B5/$B$9) -> 0.765625
A6: Interprétation à valider | B6: =COUNTIF(Requis!$J:$J,A6) -> 12 | C6: =IF($B$9=0,0,B6/$B$9) -> 0.1875
A7: Proposition (énoncé vide) | B7: =COUNTIF(Requis!$J:$J,A7) -> 1 | C7: =IF($B$9=0,0,B7/$B$9) -> 0.015625
A8: Qualification à faire | B8: =COUNTIF(Requis!$J:$J,A8) -> 2 | C8: =IF($B$9=0,0,B8/$B$9) -> 0.03125
A9: Total | B9: =SUM(B5:B8) -> 64 | C9: =SUM(C5:C8) -> 1
A10: Lignes de requis dans le Word (contrôle) | B10: =COUNTA(Requis!$B$2:$B$65) -> 64
A11: Requis sans programme cité | B11: =COUNTIF(Requis!$G$2:$G$65,"") -> 0
A12: Requis sans test automatique | B12: =COUNTIF(Requis!$I$2:$I$65,0) -> 0
A13: Commentaires de Sébastien traités | B13: =COUNTA('Commentaires Sébastien'!$A$2:$A$5) -> 4
A14: Points ouverts à faire valider | B14: =COUNTA('Points ouverts'!$A$2:$A$18) -> 17
A15: Tests automatiques | B15: =COUNTA(Tests!$C$2:$C$132) -> 131
A16: Fichiers de programme | B16: =COUNTA(Programmes!$A$2:$A$46) -> 45
A18: Par section du Word
A19: Section | B19: Implémenté et testé | C19: Interprétation à valider | D19: Proposition (énoncé vide) | E19: Qualification à faire | F19: Total
A20: 2.1 Caractéristiques des sources | B20: =COUNTIFS(Requis!$A:$A,$A20,Requis!$J:$J,B$19) -> 6 | C20: =COUNTIFS(Requis!$A:$A,$A20,Requis!$J:$J,C$19) -> 0 | D20: =COUNTIFS(Requis!$A:$A,$A20,Requis!$J:$J,D$19) -> 0 | E20: =COUNTIFS(Requis!$A:$A,$A20,Requis!$J:$J,E$19) -> 0 | F20: =SUM(B20:E20) -> 6
A21: 2.2 Contenu des sources | B21: =COUNTIFS(Requis!$A:$A,$A21,Requis!$J:$J,B$19) -> 2 | C21: =COUNTIFS(Requis!$A:$A,$A21,Requis!$J:$J,C$19) -> 1 | D21: =COUNTIFS(Requis!$A:$A,$A21,Requis!$J:$J,D$19) -> 0 | E21: =COUNTIFS(Requis!$A:$A,$A21,Requis!$J:$J,E$19) -> 0 | F21: =SUM(B21:E21) -> 3
A22: 2.3 Caractéristiques des fichiers | B22: =COUNTIFS(Requis!$A:$A,$A22,Requis!$J:$J,B$19) -> 7 | C22: =COUNTIFS(Requis!$A:$A,$A22,Requis!$J:$J,C$19) -> 4 | D22: =COUNTIFS(Requis!$A:$A,$A22,Requis!$J:$J,D$19) -> 0 | E22: =COUNTIFS(Requis!$A:$A,$A22,Requis!$J:$J,E$19) -> 0 | F22: =SUM(B22:E22) -> 11
A23: 6 (Word) Architecture | B23: =COUNTIFS(Requis!$A:$A,$A23,Requis!$J:$J,B$19) -> 6 | C23: =COUNTIFS(Requis!$A:$A,$A23,Requis!$J:$J,C$19) -> 1 | D23: =COUNTIFS(Requis!$A:$A,$A23,Requis!$J:$J,D$19) -> 0 | E23: =COUNTIFS(Requis!$A:$A,$A23,Requis!$J:$J,E$19) -> 1 | F23: =SUM(B23:E23) -> 8
A24: 3.1 Définition de la base de temps | B24: =COUNTIFS(Requis!$A:$A,$A24,Requis!$J:$J,B$19) -> 5 | C24: =COUNTIFS(Requis!$A:$A,$A24,Requis!$J:$J,C$19) -> 2 | D24: =COUNTIFS(Requis!$A:$A,$A24,Requis!$J:$J,D$19) -> 0 | E24: =COUNTIFS(Requis!$A:$A,$A24,Requis!$J:$J,E$19) -> 1 | F24: =SUM(B24:E24) -> 8
A25: 4.1 Fenêtre principale | B25: =COUNTIFS(Requis!$A:$A,$A25,Requis!$J:$J,B$19) -> 7 | C25: =COUNTIFS(Requis!$A:$A,$A25,Requis!$J:$J,C$19) -> 0 | D25: =COUNTIFS(Requis!$A:$A,$A25,Requis!$J:$J,D$19) -> 0 | E25: =COUNTIFS(Requis!$A:$A,$A25,Requis!$J:$J,E$19) -> 0 | F25: =SUM(B25:E25) -> 7
A26: 4.2 Arbre des données | B26: =COUNTIFS(Requis!$A:$A,$A26,Requis!$J:$J,B$19) -> 3 | C26: =COUNTIFS(Requis!$A:$A,$A26,Requis!$J:$J,C$19) -> 1 | D26: =COUNTIFS(Requis!$A:$A,$A26,Requis!$J:$J,D$19) -> 0 | E26: =COUNTIFS(Requis!$A:$A,$A26,Requis!$J:$J,E$19) -> 0 | F26: =SUM(B26:E26) -> 4
A27: 4.3 Modèles | B27: =COUNTIFS(Requis!$A:$A,$A27,Requis!$J:$J,B$19) -> 1 | C27: =COUNTIFS(Requis!$A:$A,$A27,Requis!$J:$J,C$19) -> 0 | D27: =COUNTIFS(Requis!$A:$A,$A27,Requis!$J:$J,D$19) -> 0 | E27: =COUNTIFS(Requis!$A:$A,$A27,Requis!$J:$J,E$19) -> 0 | F27: =SUM(B27:E27) -> 1
A28: 4.4 Outils graphiques | B28: =COUNTIFS(Requis!$A:$A,$A28,Requis!$J:$J,B$19) -> 7 | C28: =COUNTIFS(Requis!$A:$A,$A28,Requis!$J:$J,C$19) -> 2 | D28: =COUNTIFS(Requis!$A:$A,$A28,Requis!$J:$J,D$19) -> 0 | E28: =COUNTIFS(Requis!$A:$A,$A28,Requis!$J:$J,E$19) -> 0 | F28: =SUM(B28:E28) -> 9
A29: 4.5 Traitement conditionnel | B29: =COUNTIFS(Requis!$A:$A,$A29,Requis!$J:$J,B$19) -> 0 | C29: =COUNTIFS(Requis!$A:$A,$A29,Requis!$J:$J,C$19) -> 0 | D29: =COUNTIFS(Requis!$A:$A,$A29,Requis!$J:$J,D$19) -> 1 | E29: =COUNTIFS(Requis!$A:$A,$A29,Requis!$J:$J,E$19) -> 0 | F29: =SUM(B29:E29) -> 1
A30: 5 Sortie (rapport) | B30: =COUNTIFS(Requis!$A:$A,$A30,Requis!$J:$J,B$19) -> 5 | C30: =COUNTIFS(Requis!$A:$A,$A30,Requis!$J:$J,C$19) -> 1 | D30: =COUNTIFS(Requis!$A:$A,$A30,Requis!$J:$J,D$19) -> 0 | E30: =COUNTIFS(Requis!$A:$A,$A30,Requis!$J:$J,E$19) -> 0 | F30: =SUM(B30:E30) -> 6
A31: Total | B31: =SUM(B20:B30) -> 49 | C31: =SUM(C20:C30) -> 12 | D31: =SUM(D20:D30) -> 1 | E31: =SUM(E20:E30) -> 2 | F31: =SUM(F20:F30) -> 64
A33: Lecture des statuts :
A34: • Implémenté et testé : fonction présente et vérifiée par au moins un test automatique (131 tests, tous OK).
A35: • Interprétation à valider : réalisé selon une interprétation documentée (onglet « Points ouverts ») à confirmer par Sébastien.
A36: • Proposition (énoncé vide) : REQ 5500 n'a pas d'énoncé dans la Rev. A ; une fonction est proposée.
A37: • Qualification à faire : réalisé et testé sous Linux ; essai à consigner sur Windows 11 / SLES 15 SP7 réels (3000) ou sur volumes réels (4105).
A38: Vérifications faites le 28/10/2026 : 64 lignes du Word toutes présentes dans la matrice, chaque requis cité dans le code et dans au moins un test
A39: (tools/verifier_tracabilite.py : « Traçabilité complète ») ; chaque fichier, fonction et test cité ici existe ; 131/131 tests OK (Python 3.11 de référence,
A40: et campagne Python 3.10 à 3.14, Tk 8.6 et 9). Colonne jaune « Réponse de Sébastien » de l'onglet Points ouverts : à remplir lors de la revue.

Sheet Requis
A1: Section du Word | B1: Requis | C1: Énoncé d'origine (Word Rev. A) | D1: Commentaire de Sébastien (Word) | E1: Ce qui est demandé (lecture) | F1: Comment on l'a fait | G1: Programme(s) — fichier (fonction) | H1: Test(s) automatique(s) | I1: Nb tests | J1: Statut | K1: Statut détaillé | L1: Point(s) ouvert(s)
A2: 2.1 Caractéristiques des sources | B2: REQ_COMMON_KH_2100 | C2: The PLC can run at different frequencies. Preferred are 10 & 20ms, but the present tool can’t be disturbed by this aspect | E2: Fréquences différentes (10 et 20 ms préférées) sans perturber l'outil | F2: Raster estimé par fichier (médiane des Δt) ; toute période acceptée ; hors 10/20 ms = simple information | G2: core/time_base.py (_add_checks) | H2: test_time_base.test_preferred_frequencies_are_information_only | I2: 1 | J2: Implémenté et testé | K2: Implémenté et testé
A3: 2.1 Caractéristiques des sources | B3: REQ_COMMON_KH_2101 | C3: The PLC can consist of a system composed by several PLC | E3: Système de plusieurs PLC | F3: Paquet de données = un CSV par PLC ; plusieurs paquets possibles | G3: core/data_package.py (DataPackage, Workspace) | H3: test_package_report.test_multi_plc_package_and_comparison | I3: 1 | J3: Implémenté et testé | K3: Implémenté et testé
A4: 2.1 Caractéristiques des sources | B4: REQ_COMMON_KH_2102 | C4: The PLC can be synchronized or not | E4: PLC synchronisés ou non | F4: Chaque fichier garde sa base ; alignement par origine absolue (axe absolu) ou décalage manuel affiché ; comparaison inter-sources | G4: core/data_package.py (Timeline), core/multi_source.py | H4: test_package_report.test_absolute_timeline_aligns_plcs test_manual_offset | I4: 2 | J4: Implémenté et testé | K4: Implémenté et testé
A5: 2.1 Caractéristiques des sources | B5: REQ_COMMON_KH_2103 | C5: Each PLC will produce its own package of data with its own timestamp. | E5: Chaque PLC produit son paquet avec son horodatage | F5: Base de temps propre à chaque SourceFile | G5: core/data_package.py | H5: test_package_report.test_multi_plc_package_and_comparison | I5: 1 | J5: Implémenté et testé | K5: Implémenté et testé
A6: 2.1 Caractéristiques des sources | B6: REQ_COMMON_KH_2104 | C6: The collection of data from several sources can generate variation of frequencies, dephasing, or loss of data flow | E6: Variations de fréquence, déphasage, perte de flux | F6: Changement de fréquence (segments), déphasage interne (Δt hors grille) et inter-PLC (écart médian), fin de flux décalée | G6: core/time_base.py, core/multi_source.py | H6: test_time_base.test_frequency_change_segments test_many_frequency_changes_stay_linear test_package_report.test_phase_between_synchronised_plcs test_loss_of_data_flow_between_plcs | I6: 4 | J6: Implémenté et testé | K6: Implémenté et testé
A7: 2.1 Caractéristiques des sources | B7: REQ_COMMON_KH_2105 | C7: Single or multiple files | E7: Fichier unique ou multiple | F7: Ouverture de plusieurs CSV ou d'un dossier (récursif) ; un fichier illisible n'empêche pas les autres | G7: gui/app.py (open_files, open_folder, _load) | H7: test_csv_reader.test_unreadable_file_isolated test_gui.test_tree_levels_and_types | I7: 2 | J7: Implémenté et testé | K7: Implémenté et testé
A8: 2.2 Contenu des sources | B8: REQ_COMMON_KH_2200 | C8: Binary signal | E8: Signal binaire | F8: Type Bool (true/false ou 0/1), tracé en escalier sur piste logique | G8: core/signals.py, plotting/renderer.py | H8: test_csv_reader.test_auto_types | I8: 1 | J8: Implémenté et testé | K8: Implémenté et testé
A9: 2.2 Contenu des sources | B9: REQ_COMMON_KH_2201 (1re ligne) | C9: Analog signal type : float | E9: Signal analogique : float | F9: Type Float, tracé continu, lu au plus proche échantillon | G9: core/signals.py | H9: test_csv_reader.test_auto_types | I9: 1 | J9: Implémenté et testé | K9: Implémenté et testé | L9: n° 5
A10: 2.2 Contenu des sources | B10: REQ_COMMON_KH_2201 (2e ligne) | C10: Binary group signal | E10: Signal groupe binaire | F10: Groupe de Bool (détecté pour NOM[i]/NOM.i ou créé par l'utilisateur), pistes regroupées et mot binaire lu au curseur | G10: core/signals.py (BinaryGroup), core/curves.py | H10: test_csv_reader.test_indexed_binary_groups test_gui.test_tree_levels_and_types | I10: 2 | J10: Interprétation à valider | K10: Implémenté — interprétation à valider (codage du groupe) | L10: n° 5
A11: 2.3 Caractéristiques des fichiers | B11: REQ_COMMON_KH_2300 | C11: The preferred format shall be ‘csv’ | E11: Format préféré csv | F11: Toute extension lisible ; extension ≠ .csv signalée | G11: core/csv_reader.py (_check_file) | H11: test_csv_reader.test_other_extension_warned | I11: 1 | J11: Implémenté et testé | K11: Implémenté et testé
A12: 2.3 Caractéristiques des fichiers | B12: REQ_COMMON_KH_2301 | C12: Separator shall be a comma ‘,’ | E12: Séparateur virgule | F12: Contrôle de cohérence du nombre de champs par séparateur candidat (« ; » avec virgule décimale, tabulation, « | » refusés) ; lignes au mauvais nombre de champs rejetées, listées avec leur extrait ; virgule décimale dans un fichier à virgules : refus expliqué, aucune fausse colonne créée | G12: core/csv_reader.py (_check_separator) | H12: test_csv_reader.test_semicolon_separator_rejected test_robustesse.test_semicolon_with_decimal_comma_rejected test_decimal_comma_in_comma_file_never_invents_columns test_rows_with_wrong_width_rejected_and_quoted test_block_boundaries_never_change_the_result | I12: 5 | J12: Implémenté et testé | K12: Implémenté et testé | L12: n° 14
A13: 2.3 Caractéristiques des fichiers | B13: REQ_COMMON_KH_2302 | C13: Text format UTF8 | E13: Texte UTF-8 | F13: Contrôle UTF-8 de tout le fichier ; BOM toléré (information) ; octets non UTF-8 lus en Windows-1252 et UTF-16 lu, avec non-conformité ERREUR citant la 1re ligne fautive (les mesures restent exploitables) ; octets nuls signalés | G13: core/csv_reader.py | H13: test_csv_reader.test_non_utf8_read_but_flagged_with_requirement test_bom_tolerated_and_reported test_robustesse.test_invalid_byte_in_the_middle_is_flagged_not_fatal test_utf16_is_read_and_flagged | I13: 4 | J13: Interprétation à valider | K13: Implémenté — interprétation à valider (lecture signalée plutôt que refus)
A14: 2.3 Caractéristiques des fichiers | B14: REQ_COMMON_KH_2303 | C14: No additional meta data | E14: Pas de métadonnées | F14: Préambule de métadonnées repéré quelle que soit sa largeur (l'en-tête est la ligne qui précède la 1re ligne de mesures), lignes « # » ; signalés (non-conformité) et ignorés | G14: core/csv_reader.py (_locate_header) | H14: test_csv_reader.test_metadata_lines_reported_and_skipped test_robustesse.test_preamble_of_same_width_is_metadata | I14: 2 | J14: Implémenté et testé | K14: Implémenté et testé
A15: 2.3 Caractéristiques des fichiers | B15: REQ_COMMON_KH_2304 | C15: First column devoted to time base | E15: 1re colonne = base de temps | F15: Toujours la 1re colonne, quel que soit son nom | G15: core/csv_reader.py, core/time_parser.py | H15: test_csv_reader.test_reads_examples_and_keeps_first_column_as_time | I15: 1 | J15: Implémenté et testé | K15: Implémenté et testé
A16: 2.3 Caractéristiques des fichiers | B16: REQ_COMMON_KH_2305 | C16: Time stamp configuration: | D16: Sébastien Kubasik : Attention au pretrig! Est ce que temps négatif / reference absolue comme en Alspa??? | E16: Configuration de l'horodatage | F16: Dialogue Base de temps : format, unité, période, tolérance, origine absolue, décalage, jitter ; pré-déclenchement en temps négatif (remarque du relecteur) | G16: core/time_parser.py (TimeBaseSettings), gui/dialogs/time_base_dialog.py | H16: test_time_parser.test_counter_with_assumed_unit_and_pretrig test_unknown_format_is_an_error_not_a_crash | I16: 2 | J16: Interprétation à valider | K16: Implémenté — interprétation à valider (pré-déclenchement) | L16: n° 1
A17: 2.3 Caractéristiques des fichiers | B17: REQ_COMMON_KH_2306 | C17: Hh:mn:s… micro, nanos… | E17: hh:mn:s… micro, nanos… | F17: hh:mm:ss.fraction jusqu'à 9 chiffres ou .mmm.uuu.nnn, passage de minuit (une heure isolée aberrante, vers l'arrière ou vers l'avant, n'en est pas un), calcul en ns entières, colonne décodée d'un coup (écritures atypiques reprises ligne par ligne) | G17: core/time_parser.py (_convert_time_of_day, _day_offsets), core/vector_parse.py | H17: test_time_parser.test_time_of_day_fraction_styles_and_midnight test_column_and_line_by_line_conversions_agree test_robustesse.test_isolated_forward_clock_value_does_not_shift_the_rest_by_a_day | I17: 3 | J17: Implémenté et testé | K17: Implémenté et testé
A18: 2.3 Caractéristiques des fichiers | B18: REQ_COMMON_KH_2307 | C18: Time counter | E18: Compteur de temps | F18: Compteur ns, µs, ms, s, min, h ou cycles PLC ; unité lue dans l'en-tête ; sinon unité de la préférence SUPPOSÉE et signalée en avertissement (TBM non masquable) jusqu'à confirmation, applicable d'un coup à plusieurs fichiers ; grands entiers exacts | G18: core/time_parser.py (_convert_counter) | H18: test_time_parser.test_unit_from_header test_cycle_unit_requires_period test_big_integer_counter_keeps_precision test_big_integer_counter_with_odd_rows test_robustesse.test_assumed_unit_is_a_warning test_gui.test_unit_confirmed_for_several_files | I18: 6 | J18: Interprétation à valider | K18: Implémenté — interprétation à valider (unité d'un compteur sans unité) | L18: n° 10
A19: 2.3 Caractéristiques des fichiers | B19: REQ_COMMON_KH_2308 | C19: First row devoted to column’s header | E19: 1re ligne = en-têtes | F19: 1re ligne utile = en-tête ; sans en-tête, la 1re ligne de mesures est conservée et les colonnes nommées Colonne_1… ; en-tête répété au milieu (fichiers concaténés) ignoré et signalé | G19: core/csv_reader.py (normalize_header) | H19: test_csv_reader.test_numeric_first_line_flagged test_robustesse.test_missing_header_keeps_the_first_measure test_repeated_header_and_concatenated_captures | I19: 3 | J19: Implémenté et testé | K19: Implémenté et testé
A20: 2.3 Caractéristiques des fichiers | B20: REQ_COMMON_KH_2309 | C20: Composed by PLC’s variables names | E20: Noms des variables PLC | F20: Noms vides et doublons renommés et signalés | G20: core/csv_reader.py (normalize_header) | H20: test_csv_reader.test_header_names_normalized | I20: 1 | J20: Implémenté et testé | K20: Implémenté et testé
A21: 2.3 Caractéristiques des fichiers | B21: REQ_COMMON_KH_2310 | C21: Maximal size xxxMo | E21: Taille maximale « xxxMo » | F21: Paramètre max_file_size_mb (défaut 500 Mo, Outils > Préférences) ; fichier refusé au-delà ; valeur à fixer avec le banc tools/banc_performance.py sur les postes cibles | G21: config.py, core/csv_reader.py | H21: test_csv_reader.test_size_limit | I21: 1 | J21: Interprétation à valider | K21: Implémenté — interprétation à valider (valeur xxx) | L21: n° 2
A22: 6 (Word) Architecture | B22: REQ_COMMON_KH_3000 | C22: Final tool shall be compatible with SLES - SUSE 15 SP7: ‘SUSE Linux Enterprise Server 15SP7’ at least | D22: Sébastien Kubasik : Ou Windows!? Besoin de déterminer la cible ou double compatibilité | E22: Compatible SLES 15 SP7 au moins (+ Windows, remarque du relecteur) | F22: Python + Tk + numpy + matplotlib, wheels vérifiées pour win_amd64 et manylinux (glibc 2.38 de SP7) ; scripts SLES et Windows ; Spyder 6 | G22: system/compat.py, install/ | H22: test_architecture.test_minimal_python_syntax campagne multi-versions | I22: 1 | J22: Qualification à faire | K22: Implémenté — qualification sur cible à faire (Windows 11, SLES 15 SP7) | L22: n° 4
A23: 6 (Word) Architecture | B23: REQ_COMMON_KH_3001 | C23: Final tool shall be compatible with Python 3.6 at least | D23: Sébastien Kubasik : Ces versions évolueront forcément, c’est ici le point de départ observé avec le package TDS V1.1.0. Semble possible de disposer d’un upgrade Python3.11 pour SLES 15 | E23: Compatible Python 3.6 au moins | F23: Lu comme « 3.6 minimum » : code vérifié de 3.10 à 3.14, référence 3.11 (décision du relecteur : Python 3.11 sur SLES 15) | G23: version.py (MIN_PYTHON) | H23: test_architecture.test_minimal_python_syntax | I23: 1 | J23: Interprétation à valider | K23: Implémenté — interprétation à valider (3.6 strict exclu) | L23: n° 3
A24: 6 (Word) Architecture | B24: REQ_COMMON_KH_3002 | C24: MAIN.py script shall be devoted only to generate the GUI interface. | E24: MAIN.py dédié à la génération de l'IHM | F24: MAIN.py n'importe que l'IHM et ne contient que build_interface et main | G24: MAIN.py | H24: test_architecture.test_main_only_builds_the_gui | I24: 1 | J24: Implémenté et testé | K24: Implémenté et testé
A25: 6 (Word) Architecture | B25: REQ_COMMON_KH_3003 | C25: All action realized by the tool shall be best as possible externalized into a dedicated sub script or class. | E25: Actions externalisées dans des sous-scripts ou classes | F25: Contrôleur gui/app.py, traitements dans core/, dessin plotting/, rapport report/ ; core/ sans Tk | G25: ptbg/ | H25: test_architecture.test_processing_is_externalized_and_gui_free | I25: 1 | J25: Implémenté et testé | K25: Implémenté et testé
A26: 6 (Word) Architecture | B26: REQ_COMMON_KH_3004 | C26: All additional packages or library implemented shall be documented and strictly aligned with the kernel version. | D26: Sébastien Kubasik : Il y a des packages transverses toute version et d’autre plus restrictifs avec independances. Le plus fréquemment il y a une sensibilité à la version de python, l’OS, et le cœur 32 ou 63 bits | E26: Paquets documentés et alignés sur la version du noyau Python | F26: requirements.txt figé et commenté, docs/DEPENDANCES.md (versions, licences, Python supportés, wheels, impacts de montée de version), relevé au démarrage | G26: system/environment.py, requirements.txt | H26: test_architecture.test_third_party_libraries_are_documented_and_pinned | I26: 1 | J26: Implémenté et testé | K26: Implémenté et testé
A27: 6 (Word) Architecture | B27: REQ_COMMON_KH_3005 | C27: Compatibility mechanism between different OS Shall be documented. | E27: Mécanisme de compatibilité entre OS documenté | F27: Différences d'OS centralisées dans system/compat.py ; docs/COMPATIBILITE_OS.md | G27: system/compat.py | H27: test_architecture.test_os_specific_code_is_centralized | I27: 1 | J27: Implémenté et testé | K27: Implémenté et testé
A28: 6 (Word) Architecture | B28: REQ_COMMON_KH_3006 | C28: Code source shall be commented | E28: Code source commenté | F28: Docstring par module, classe et fonction non triviale ; requis cités dans le code | G28: tout ptbg/ | H28: test_architecture.test_sources_are_commented | I28: 1 | J28: Implémenté et testé | K28: Implémenté et testé
A29: 6 (Word) Architecture | B29: REQ_COMMON_KH_3007 | C29: No useless function hold into the scripts | E29: Aucune fonction inutile | F29: Contrôle automatique : toute fonction définie est appelée ; analyse vulture | G29: tout ptbg/ | H29: test_architecture.test_no_unused_functions | I29: 1 | J29: Implémenté et testé | K29: Implémenté et testé
A30: 3.1 Définition de la base de temps | B30: REQ_COMMON_KH_4100 | C30: The present tool shall define the time raster from the source and control check:•Period value•Period stability•Period continuous increase | E30: Raster défini et contrôlé : valeur, stabilité, croissance continue | F30: 3 contrôles nommés (+ données manquantes), statut OK / AVERTISSEMENT / ERREUR | G30: core/time_base.py (analyze, _add_checks) | H30: test_time_base.test_perfect_raster test_duplicates_and_backward_are_errors | I30: 2 | J30: Interprétation à valider | K30: Implémenté — interprétation à valider (tolérance 10 %, 10 intervalles) | L30: n° 9
A31: 3.1 Définition de la base de temps | B31: REQ_COMMON_KH_4101 | C31: The present tool shall be capable to find and highlight the inconsistent time base like missing data or wrong phasing | E31: Repérer et mettre en évidence les incohérences (données manquantes, mauvais phasage) | F31: Trous (k × T), déphasage, doublons, retours arrière, horodatages illisibles et aberrants isolés ; marqueurs dans le TBM (y compris pour les horodatages illisibles), liste avec ligne CSV ; courbes interrompues ; croix sur cellules vides ; valeurs « nan »/« inf » et valeurs incompatibles avec le type comptées par variable | G31: core/time_base.py, plotting/monitor.py, core/sampling.py | H31: test_time_base.test_missing_samples_detected_and_kept_in_regular_time test_wrong_phasing_detected test_robustesse.test_isolated_aberrant_timestamp_is_one_error_not_a_fake_gap test_nan_and_inf_are_missing_values_not_text | I31: 4 | J31: Implémenté et testé | K31: Implémenté et testé
A32: 3.1 Définition de la base de temps | B32: REQ_COMMON_KH_4102 | C32: A dedicated graphical axle shall be devoted to detail the time base conversion and status. It shall be automatically present on each graphical template and call: Time Base Monitor. | E32: Axe dédié « Time Base Monitor » détaillant conversion et statut, présent sur chaque template | F32: Ajouté automatiquement sous chaque disposition, même axe des temps ; texte de conversion et statut par fichier | G32: plotting/monitor.py, plotting/renderer.py | H32: test_package_report.test_every_template_has_time_base_monitor | I32: 1 | J32: Implémenté et testé | K32: Implémenté et testé
A33: 3.1 Définition de la base de temps | B33: REQ_COMMON_KH_4103 | C33: The time base monitor can be hidden by the issuer only if no warning or error. | E33: Masquable seulement sans avertissement ni erreur | F33: Bouton refusé avec explication ; réaffichage automatique si une alerte apparaît | G33: plotting/monitor.py (can_hide), gui/analysis_tab.py | H33: test_package_report.test_monitor_hiding_rules test_gui.test_monitor_hide_rules | I33: 2 | J33: Implémenté et testé | K33: Implémenté et testé
A34: 3.1 Définition de la base de temps | B34: REQ_COMMON_KH_4104 | C34: The Time Base Monitor shall be automatically present into all reports. If removed for arrangement and indication shall appear to confirm the good construction or Time Base. | E34: Présent dans tous les rapports ; sinon indication de bonne construction | F34: TBM sur chaque page ; s'il a été masqué, encadré « construction de la base de temps vérifiée : CONFORME » | G34: plotting/renderer.py, plotting/monitor.py (confirmation_text) | H34: test_package_report.test_report_note_when_monitor_hidden | I34: 1 | J34: Implémenté et testé | K34: Implémenté et testé
A35: 3.1 Définition de la base de temps | B35: REQ_COMMON_KH_4105 | C35: In case of disturbance in the time base analysis, the treatment can’t be locked or unstable. | E35: Traitement jamais bloqué ni instable | F35: Lecture par blocs, annulable, en arrière-plan ; lignes ordinaires découpées d'un coup et colonnes converties en entier (core/vector_parse.py), lignes et cellules particulières traitées une à une avec les mêmes règles (résultats identiques) ; une ligne malade (guillemet non fermé, octets nuls, cellule démesurée) n'atteint jamais la suite ; une erreur imprévue sur un fichier le marque en erreur sans arrêter les autres ; analyse vectorisée O(n) (changements de fréquence et croix des cellules vides compris), événements plafonnés ; curseurs redessinés seuls (blitting), abscisses et nuage X/Y en cache ; axe en défaut remplacé par un message ; banc de 130 fichiers pathologiques et 40 corruptions aléatoires sans exception ; banc de mesure tools/banc_performance.py | G35: gui/tasks.py, core/csv_reader.py, core/vector_parse.py, core/data_package.py (load_source), core/time_base.py, core/sampling.py, plotting/renderer.py, gui/analysis_tab.py | H35: test_robustesse (31 cas dont test_random_corruptions_never_raise test_unexpected_error_is_isolated_to_its_file test_block_boundaries_never_change_the_result) test_time_base.test_pathological_inputs_never_raise test_large_series_speed test_many_frequency_changes_stay_linear test_csv_reader.test_cancellation test_mixed_columns_converted_like_cell_by_cell test_analysis_tools.test_missing_markers_many_runs_stay_fast test_xy_cloud_is_cached_until_data_change test_gui.test_tracking_mode | I35: 12 | J35: Qualification à faire | K35: Implémenté — qualification sur volumes réels à faire | L35: n° 16
A36: 3.1 Définition de la base de temps | B36: REQ_COMMON_KH_4106 | C36: In case of disturbance in the time base analysis, the user can specify the normal raster with an associated diagnosis | E36: L'utilisateur peut spécifier le raster normal avec un diagnostic associé | F36: Période nominale + tolérance + diagnostic opérateur (imprimé dans le TBM et le rapport) | G36: gui/dialogs/time_base_dialog.py, core/data_package.py (configure_time) | H36: test_time_base.test_user_nominal_period test_package_report.test_project_roundtrip_with_relative_paths | I36: 2 | J36: Implémenté et testé | K36: Implémenté et testé
A37: 3.1 Définition de la base de temps | B37: REQ_COMMON_KH_4107 | C37: Constitute Absolute timestamp. Clock Jitter ignored | E37: Horodatage absolu ; jitter d'horloge ignoré | F37: Origine absolue (hh:mm:ss, date-heure ou saisie) et axe absolu ; le jitter dans la tolérance n'est pas une anomalie ; affichage de l'horodatage BRUT par défaut, régularisation sur le raster en option par fichier (indiquée dans le TBM) | G37: core/time_parser.py, core/time_base.py (_regularize), core/data_package.py (Timeline) | H37: test_time_base.test_jitter_ignored_within_tolerance test_robustesse.test_raw_timestamps_are_displayed_by_default test_package_report.test_absolute_timeline_aligns_plcs test_gui.test_absolute_time_mode | I37: 4 | J37: Interprétation à valider | K37: Implémenté — interprétation à valider (affichage brut par défaut) | L37: n° 7, n° 8
A38: 4.1 Fenêtre principale | B38: REQ_COMMON_KH_5100 | C38: Top bar with main menu path | E38: Barre supérieure avec menu principal et chemin | F38: Menus Fichier / Affichage / Base de temps / Outils / Rapport / Information + barre de chemin « paquet > fichier > variable » | G38: gui/menu_bar.py, gui/path_bar.py | H38: test_gui.test_main_window_layout | I38: 1 | J38: Implémenté et testé | K38: Implémenté et testé
A39: 4.1 Fenêtre principale | B39: REQ_COMMON_KH_5101 | C39: Specific ‘Information’ section including:Tool versionHistory of changesSourcesHelp file | E39: Section Information : version, historique, sources, aide | F39: Menu Information : version, CHANGELOG, sources (empreintes du code, bibliothèques, fichiers), aide, journal, traçabilité | G39: gui/info_windows.py | H39: test_gui.test_information_windows_and_tree_toggle | I39: 1 | J39: Implémenté et testé | K39: Implémenté et testé
A40: 4.1 Fenêtre principale | B40: REQ_COMMON_KH_5102 | C40: Bottom bar summarizing:UserDateActivity logTool version | E40: Barre inférieure : utilisateur, date, journal, version | F40: Barre d'état avec horloge, dernier message (clic = journal complet), version, avancement | G40: gui/status_bar.py, system/activity_log.py | H40: test_gui.test_main_window_layout | I40: 1 | J40: Implémenté et testé | K40: Implémenté et testé
...

Sheet Commentaires Sébastien
A1: Requis | B1: Auteur | C1: Commentaire (Word) | D1: Réponse apportée | E1: Où (programme / document) | F1: Vérification | G1: Statut | H1: Point ouvert
A2: REQ_COMMON_KH_2305 | B2: Sébastien Kubasik | C2: Attention au pretrig! Est ce que temps négatif / reference absolue comme en Alspa??? | D2: Pré-déclenchement géré : un compteur peut être négatif, t = 0 est l'instant de déclenchement, trait pointillé « déclenchement (t = 0) » sur les axes ; l'origine absolue saisie (Base de temps > Configurer) est la date-heure du déclenchement, ce qui donne l'axe absolu « comme en ALSPA ». Nombre d'échantillons de pré-déclenchement signalé (information). | E2: core/time_parser.py (TimeBaseSettings, _convert_counter) ; plotting/renderer.py (_draw_time_axle) ; gui/dialogs/time_base_dialog.py | F2: test_time_parser.test_counter_with_assumed_unit_and_pretrig ; test_counter_with_absolute_origin | G2: Interprétation à valider | H2: n° 1
A3: REQ_COMMON_KH_3000 | B3: Sébastien Kubasik | C3: Ou Windows!? Besoin de déterminer la cible ou double compatibilité | D3: Double compatibilité retenue (décision du demandeur) : Windows 11 64 bits sous Spyder 6 ET SLES 15 SP7. Un seul code ; toutes les différences d'OS isolées dans ptbg/system/compat.py ; scripts d'installation et de lancement pour les deux systèmes ; wheels vérifiées win_amd64 et manylinux (glibc 2.38 de SP7). | E3: ptbg/system/compat.py ; install/ ; docs/COMPATIBILITE_OS.md | F3: test_architecture.test_os_specific_code_is_centralized ; campagne 7 combinaisons (Tk 8.6 et 9) | G3: Qualification sur cible à faire | H3: n° 4
A4: REQ_COMMON_KH_3001 | B4: Sébastien Kubasik | C4: Ces versions évolueront forcément, c’est ici le point de départ observé avec le package TDS V1.1.0. Semble possible de disposer d’un upgrade Python3.11 pour SLES 15 | D4: Python 3.6 lu comme un minimum : référence Python 3.11 (upgrade possible sur SLES 15, comme indiqué), code vérifié de 3.10 à 3.14. Python 3.6 (fin de vie 2021) imposerait numpy 1.19 / matplotlib 3.3 : non retenu. Version minimale contrôlée au lancement par MAIN.py. | E4: ptbg/version.py (MIN_PYTHON) ; MAIN.py | F4: test_architecture.test_minimal_python_syntax ; campagne Python 3.10 → 3.14 | G4: Interprétation à valider | H4: n° 3
A5: REQ_COMMON_KH_3004 | B5: Sébastien Kubasik | C5: Il y a des packages transverses toute version et d’autre plus restrictifs avec independances. Le plus fréquemment il y a une sensibilité à la version de python, l’OS, et le cœur 32 ou 63 bits | D5: Sensibilités relevées par Sébastien traitées : versions figées dans requirements.txt (identiques Python 3.11 à 3.14, Windows et SLES) ; DEPENDANCES.md donne pour chaque paquet la version, le type (direct / transitif), les Python supportés, les wheels win_amd64 / manylinux, la licence, et distingue les composants compilés (sensibles à Python, à l'OS et au 32/64 bits : numpy, matplotlib, contourpy, kiwisolver, pillow) du Python pur. Cible 64 bits uniquement. Relevé des versions au démarrage et outil d'audit. | E5: requirements.txt ; docs/DEPENDANCES.md ; ptbg/system/environment.py ; tools/audit_environnement.py | F5: test_architecture.test_third_party_libraries_are_documented_and_pinned | G5: Implémenté et testé | H5: —

Sheet Points ouverts
A1: N° | B1: Requis concerné(s) | C1: Question posée | D1: Interprétation retenue (à valider par Sébastien) | E1: Où la modifier | F1: Réponse de Sébastien
A2: 1 | B2: REQ_COMMON_KH_2305 (commentaire « attention au pretrig ! temps négatif / référence absolue comme en ALSPA ? ») | C2: Comment est représenté le pré-déclenchement ? | D2: Un compteur peut être négatif ; t = 0 est l'instant de déclenchement ; l'origine absolue saisie est la date-heure de ce déclenchement. Les temps négatifs sont conservés et une ligne « déclenchement (t = 0) » est tracée. | E2: core/time_parser.py, plotting/renderer.py
A3: 2 | B3: REQ_COMMON_KH_2310 « Maximal size xxxMo » | C3: Quelle taille maximale ? | D3: Paramètre max_file_size_mb, défaut **500 Mo** (≈ 0,5 à 1 Go de mémoire), modifiable dans Outils > Préférences. | E3: config.py
A4: 3 | B4: REQ_COMMON_KH_3001 « Python 3.6 at least » (commentaire : upgrade Python 3.11 possible sur SLES 15) | C4: 3.6 est-il un minimum ou une cible stricte ? | D4: Lu comme un minimum : développement en **3.11**, code vérifié de 3.10 à 3.14. Python 3.6 (fin de vie 2021) n'est pas supporté : il imposerait numpy 1.19 / matplotlib 3.3. | E4: version.py (MIN_PYTHON)
A5: 4 | B5: REQ_COMMON_KH_3000 (commentaire « ou Windows ? double compatibilité ») | C5: Quelle cible ? | D5: **Double compatibilité** Windows 11 64 bits (Spyder 6) et SLES 15 SP7, confirmée par le demandeur. | E5: system/compat.py
A6: 5 | B6: REQ_COMMON_KH_2201 (2e occurrence) « Binary group signal » — identifiant dupliqué | C6: Qu'est-ce qu'un groupe binaire dans les CSV PTBG ? Faut-il renuméroter l'exigence ? | D6: Ensemble ordonné de colonnes Bool (bit 0 = 1er membre) : détecté automatiquement pour NOM[i] / NOM.i, ou créé par l'utilisateur ; affiché en pistes regroupées, lu comme mot binaire. Un mot entier codant des bits n'est pas décodé. | E6: core/signals.py (BinaryGroup, detect_indexed_groups)
A7: 6 | B7: REQ_COMMON_KH_5202 « type Bool or Float » | C7: Existe-t-il une convention de typage dans les CSV ? | D7: Règle automatique : true/false, ou nombres 0/1 avec au moins un 0 et un 1 → Bool ; sinon Float. Une colonne constante reste Float. Colonnes d'états texte (« STOP », « ACTIVE », vus dans les CSV de simulation) → type Texte, hors spécification. Type forçable par variable. | E7: core/signals.py (auto_type)
A8: 7 | B8: REQ_COMMON_KH_4107 « Constitute absolute timestamp. Clock jitter ignored » | C8: Que signifie « jitter ignoré » ? | D8: Le jitter dans la tolérance **n'est pas une anomalie** (il est mesuré et affiché, pas compté comme défaut). L'axe des temps affiche par défaut l'**horodatage brut** du fichier : rien n'est recalé en silence. En option, par fichier, un affichage **régularisé** (droite t = a + T·k ajustée par blocs alignés, trous conservés, aucune mesure créée), toujours indiqué dans le TBM et le rapport. | E8: core/time_base.py (_regularize), dialogue Base de temps
A9: 8 | B9: REQ_COMMON_KH_4107 / 2102 | C9: D'où vient l'origine absolue d'un compteur ? | D9: Horodatage hh:mm:ss (date saisissable) ou date-heure : absolu d'office. Compteur : origine saisie par l'utilisateur. L'axe absolu n'est proposé que si chaque fichier a une origine. Aucun recalage automatique entre PLC : décalage manuel explicite, affiché dans le TBM. | E9: core/data_package.py (Timeline)
A10: 9 | B10: REQ_COMMON_KH_4100 / 4106 — tolérance | C10: Quelle tolérance par défaut sur la période ? Combien d'intervalles pour un changement de fréquence ? | D10: Valeurs **arbitraires, non fournies par les requis** : 10 % de la période et 10 intervalles consécutifs cohérents hors raster. Ce sont des réglages utilisateur (Outils > Préférences, et tolérance par fichier dans Base de temps), affichés dans le TBM. | E10: config.py
A11: 10 | B11: REQ_COMMON_KH_2307 — unité du compteur | C11: Unité d'un compteur sans unité (colonne « index » des CSV fournis, pas de 20) ? | D11: Lue dans l'en-tête (t_ms, Temps (s), time[us]…). Sinon l'unité de la préférence (ms) est **SUPPOSÉE** et signalée en **avertissement** : « unité SUPPOSÉE, à confirmer » dans le TBM et le rapport, TBM non masquable, jusqu'à ce que l'opérateur choisisse l'unité (Base de temps > Configurer, applicable d'un coup à tous les fichiers concernés). Alternative possible si demandée : axe en « unités de compteur » sans conversion. | E11: core/time_parser.py, config.py
A12: 11 | B12: REQ_COMMON_KH_5404 (énoncé identique à 5403) | C12: Exigence différente attendue (Δt, écart de valeurs ?) | D12: Couvert par la même réalisation : C1 et C2 posés d'office avec leurs instants, plus Δt, 1/Δt et ΔV par courbe. | E12: plotting/renderer.py, core/readings.py
A13: 12 | B13: REQ_COMMON_KH_5407 / 5500 (énoncé 5500 **vide**) | C13: Quel traitement conditionnel est attendu ? | D13: Curseur horizontal : franchissements retenus seulement si la condition Bool est vraie (même ligne pour le même fichier ; dernier état connu pour un autre fichier). Section 4.5 : statistiques sous condition (durée, min, max, moyenne, écart-type, durée au-dessus d'un seuil). | E13: core/conditional.py
... A18: 17 | B18: REQ_COMMON_KH_5500 (énoncé **vide**) | C18: Le requis peut-il être déclaré satisfait ? | D18: **Non** : la fonction de statistiques conditionnelles (n° 12) est une proposition ; le requis reste à rédiger. | E18: —

Sheet Programmes
A1: Fichier | B1: Couche | C1: Rôle (docstring du module) | D1: Lignes de code | E1: Fonctions / classes | F1: Requis cités dans le code
A2: ptbg/config.py | B2: ptbg | C2: Préférences de l'outil, modifiables par Outils > Préférences. | D2: 76 | E2: 5 | F2: 2100, 2300, 2310, 4100, 4107, 6005
A3: ptbg/core/arrangement.py | B3: core | C3: Modèles de disposition (templates) et état d'un onglet graphique. | D3: 128 | E3: 13 | F3: 4102, 4103, 5106, 5300, 5400, 5401, 5402, 5405, 5406, 5407, 5408, 6004
A4: ptbg/core/conditional.py | B4: core | C4: Traitement conditionnel par signaux Bool (REQ_COMMON_KH_5407 et section 4.5). | D4: 111 | E4: 12 | F4: 5407, 5500
A5: ptbg/core/csv_reader.py | B5: core | C5: Lecture contrôlée d'un fichier CSV PTBG. | D5: 643 | E5: 39 | F5: 2300, 2301, 2302, 2303, 2304, 2308, 2309, 2310, 4105, 6005
A6: ptbg/core/curves.py | B6: core | C6: Résolution d'une courbe (``CurveRef``) en données affichables et lisibles. | D6: 61 | E6: 5 | F6: 2201
A7: ptbg/core/data_package.py | B7: core | C7: Paquets de données, fichiers sources et axe des temps commun. | D7: 281 | E7: 41 | F7: 2101, 2102, 2310, 4101, 4103, 4105, 4106, 4107, 5200, 5202
A8: ptbg/core/diagnostic_report.py | B8: core | C8: Diagnostic complet d'un fichier, en texte Markdown (fenêtre « Diagnostic »). | D8: 48 | E8: 1 | F8: 2300, 4100
A9: ptbg/core/diagnostics.py | B9: core | C9: Niveaux de gravité et constats partagés par la lecture et la base de temps. | D9: 32 | E9: 5 | F9: 2301
A10: ptbg/core/multi_source.py | B10: core | C10: Comparaison des sources d'un système multi-PLC (REQ 2100, 2101, 2102, 2104). | D10: 75 | E10: 2 | F10: 2100, 2102, 2104
A11: ptbg/core/project.py | B11: core | C11: Fichier projet « .ptbg.json » : sauvegarde et réouverture d'une analyse. | D11: 116 | E11: 8 | F11: 3005, 6004, 6005
A12: ptbg/core/readings.py | B12: core | C12: Lectures des curseurs, communes au panneau droit et au rapport PDF. | D12: 149 | E12: 9 | F12: 4105, 5401, 5402, 5403, 5405, 5406, 5408
A13: ptbg/core/sampling.py | B13: core | C13: Lecture des échantillons : curseurs, croisements, réduction d'affichage. | D13: 187 | E13: 14 | F13: 4105, 5401, 5406, 5407
... A24: ptbg/gui/graph_area.py | B24: gui | C24: Zone graphique principale, à droite (REQ_COMMON_KH_5104, 5106). | D24: 52 | E24: 7 | F24: 5104, 5300
A25: ptbg/gui/icons.py | B25: gui | C25: Petites icônes de statut dessinées pixel par pixel (aucun fichier image). | D25: 45 | E25: 6
A26: ptbg/gui/info_windows.py | B26: gui | C26: Section « Information » (REQ_COMMON_KH_5101) et fenêtres de texte. | D26: 140 | E26: 9 | F26: 3004, 5101
A27: ptbg/gui/menu_bar.py | B27: gui | C27: Barre de menus principale (REQ_COMMON_KH_5100) et section Information (5101). | D27: 92 | E27: 2 | F27: 2104, 2105, 2201, 3003, 4101, 4103, 4106, 4107, 5100, 5101, 5102, 5105, 5106, 5200, 5406, 6003, 6004, 6005
A28: ptbg/gui/path_bar.py | B28: gui | C28: Barre supérieure : chemin courant et accès rapides (REQ_COMMON_KH_5100). | D28: 35 | E28: 3 | F28: 5100
A29: ptbg/gui/reading_panel.py | B29: gui | C29: Panneau de lecture des curseurs, à droite de la zone graphique (REQ 5402). | D29: 47 | E29: 4 | F29: 5402
A30: ptbg/gui/status_bar.py | B30: gui | C30: Barre d'état en bas de la fenêtre (REQ_COMMON_KH_5102). | D30: 59 | E30: 8 | F30: 4105, 5102
A31: ptbg/gui/tasks.py | B31: gui | C31: Exécution des traitements longs hors du fil de l'interface (REQ_COMMON_KH_4105). | D31: 54 | E31: 7 | F31: 4105
A32: ptbg/gui/tree_panel.py | B32: gui | C32: Arbre des données, zone gauche de la fenêtre. | D32: 198 | E32: 13 | F32: 5103, 5105, 5200, 5201, 5202, 5203
A33: ptbg/plotting/monitor.py | B33: plotting | C33: Time Base Monitor : axe dédié à la base de temps (REQ 4102, 4103, 4104). | D33: 145 | E33: 8 | F33: 4101, 4102, 4103, 4104
A34: ptbg/plotting/renderer.py | B34: plotting | C34: Rendu d'un onglet (``TabState``) dans une figure Matplotlib. | D34: 447 | E34: 27 | F34: 2200, 4101, 4102, 4104, 4105, 5300, 5400, 5405, 5406, 5408
A35: ptbg/plotting/styles.py | B35: plotting | C35: Couleurs et tailles partagées par l'écran et le PDF. | D35: 32 | E35: 1
A36: ptbg/plotting/time_axis.py | B36: plotting | C36: Graduation de l'axe des temps (relatif en secondes ou horodatage absolu). | D36: 31 | E36: 4
A37: ptbg/report/pdf_report.py | B37: report | C37: Rapport PDF (REQ_COMMON_KH_6000 à 6005, 4104). | D37: 181 | E37: 8 | F37: 4104, 6000, 6001, 6002, 6005
A38: ptbg/system/activity_log.py | B38: system | C38: Journal d'activité de la session (REQ_COMMON_KH_5102 « Activity log »). | D38: 60 | E38: 9 | F38: 5102
A39: ptbg/system/compat.py | B39: system | C39: Mécanismes de compatibilité Windows 11 / SLES 15 SP7. | D39: 129 | E39: 10 | F39: 2310, 3000, 3005
A40: ptbg/system/environment.py | B40: system | C40: Relevé de l'environnement d'exécution (REQ_COMMON_KH_3004, 3005, 5101). | D40: 174 | E40: 13 | F40: 3004
A41: ptbg/version.py | B41: ptbg | C41: Identité de l'outil : nom, version, date et document de spécification. | D41: 17 | E41: 1 | F41: 3001, 5101, 5102, 6005
A42: MAIN.py | B42: MAIN.py | C42: VISU PTBG — script principal : construit l'interface graphique. | D42: 105 | E42: 3 | F42: 3002, 3003, 4102, 5100, 5102, 5103, 5104, 5105, 5300, 5402
A43: tools/audit_environnement.py | B43: tools | C43: Relevé et contrôle de l'environnement d'exécution (REQ_COMMON_KH_3004, 3005). | D43: 34 | E43: 1 | F43: 3004
A44: tools/banc_performance.py | B44: tools | C44: Banc de performance sur des fichiers CSV PTBG réels (REQ_COMMON_KH_2310, 4105). | D44: 90 | E44: 3 | F44: 2310
A45: tools/generer_donnees_demo.py | B45: tools | C45: Génère les CSV de démonstration de data/demo/ (reproductibles, graine fixe). | D45: 101 | E45: 6 | F45: 2100, 2104, 2201, 2301, 2305, 2306, 4100, 4101, 4107
A46: tools/verifier_tracabilite.py | B46: tools | C46: Vérifie que CHAQUE requis du document Word est tracé (aucun requis oublié). | D46: 55 | E46: 3 | F46: 3006, 3007, 4103

Sheet Tests
A1: Fichier de test | B1: Classe | C1: Test | D1: Ce qui est vérifié | E1: Requis couverts
A2: test_analysis_tools | B2: SamplingTests | C2: test_nearest_and_hold_without_interpolation | D2: REQ 5401 : valeur d'un échantillon réel, jamais interpolée. | E2: 5401
A3: test_analysis_tools | B3: SamplingTests | C3: test_unsorted_time_still_readable | E3: module : 4105, 5401, 5405, 5406, 5407, 5408, 5500
A4: test_analysis_tools | B4: SamplingTests | C4: test_unreadable_timestamps_are_skipped | D4: Horodatage illisible (NaN) : jamais lu, l'échantillon voisin réel l'est. | E4: module : 4105, 5401, 5405, 5406, 5407, 5408, 5500
A5: test_analysis_tools | B5: SamplingTests | C5: test_step_to_neighbour_sample | E5: module : 4105, 5401, 5405, 5406, 5407, 5408, 5500
A6: test_analysis_tools | B6: SamplingTests | C6: test_decimate_keeps_extremes_and_gaps | E6: module : 4105, 5401, 5405, 5406, 5407, 5408, 5500
A7: test_analysis_tools | B7: SamplingTests | C7: test_decimate_window | E7: module : 4105, 5401, 5405, 5406, 5407, 5408, 5500
A8: test_analysis_tools | B8: SamplingTests | C8: test_missing_markers_frame_empty_cells | D8: Croix sur le dernier point connu avant et le premier après une cellule vide. | E8: module : 4105, 5401, 5405, 5406, 5407, 5408, 5500
A9: test_analysis_tools | B9: SamplingTests | C9: test_missing_markers_many_runs_stay_fast | D9: REQ 4105 : 300 000 suites de cellules vides traitées sans blocage (calcul | E9: 4105
A10: test_analysis_tools | B10: SamplingTests | C10: test_break_at_gaps | E10: module : 4105, 5401, 5405, 5406, 5407, 5408, 5500
A11: test_analysis_tools | B11: SamplingTests | C11: test_crossings_with_condition | D11: REQ 5406 / 5407 : franchissements, restreints par la condition. | E11: 5406, 5407
A12: test_analysis_tools | B12: ConditionalAndXYTests | C12: test_same_file_condition_uses_same_row | E12: 5407
A13: test_analysis_tools | B13: ConditionalAndXYTests | C13: test_other_file_condition_holds_last_state | E13: 5407
A14: test_analysis_tools | B14: ConditionalAndXYTests | C14: test_and_or_combination | E14: module : 4105, 5401, 5405, 5406, 5407, 5408, 5500
A15: test_analysis_tools | B15: ConditionalAndXYTests | C15: test_conditional_statistics | D15: Section 4.5 / REQ 5500 (proposition) : statistiques sous condition. | E15: 5500
A16: test_analysis_tools | B16: ConditionalAndXYTests | C16: test_xy_same_file_and_cross_file | D16: REQ 5408 : couples même ligne, ou plus proche à moins d'une demi-période. | E16: 5408
A17: test_analysis_tools | B17: ConditionalAndXYTests | C17: test_xy_cloud_is_cached_until_data_change | D17: REQ 5408 / 4105 : le nuage n'est pas reformé à chaque mouvement de souris, mais | E17: 4105, 5408
A18: test_analysis_tools | B18: ConditionalAndXYTests | C18: test_readings_rows | D18: REQ 5401-5405 : lectures C1, C2, Δ, global et H. | E18: 5401, 5405
A19: test_architecture | B19: ArchitectureTests | C19: test_main_only_builds_the_gui | D19: REQ_COMMON_KH_3002. | E19: 3002
A20: test_architecture | B20: ArchitectureTests | C20: test_processing_is_externalized_and_gui_free | D20: REQ_COMMON_KH_3003 : core sans Tk ni Matplotlib ; dessin et rapport sans Tk. | E20: 3003
A21: test_architecture | B21: ArchitectureTests | C21: test_third_party_libraries_are_documented_and_pinned | D21: REQ_COMMON_KH_3004 : bibliothèques tierces figées et documentées, stdlib listée. | E21: 3004
A22: test_architecture | B22: ArchitectureTests | C22: test_os_specific_code_is_centralized | D22: REQ_COMMON_KH_3005 : seuls system/compat.py et environment.py testent l'OS. | E22: 3005
A23: test_architecture | B23: ArchitectureTests | C23: test_sources_are_commented | D23: REQ_COMMON_KH_3006 : docstring par module et par fonction/classe publique non triviale. | E23: 3006
A24: test_architecture | B24: ArchitectureTests | C24: test_no_unused_functions | D24: REQ_COMMON_KH_3007 : toute fonction définie est appelée quelque part. | E24: 3007
A25: test_architecture | B25: ArchitectureTests | C25: test_minimal_python_syntax | D25: REQ_COMMON_KH_3000 / 3001 : le code se compile avec la grammaire de la version minimale. | E25: 3000, 3001
A26: test_architecture | B26: ArchitectureTests | C26: test_templates_fit_their_grid | D26: REQ_COMMON_KH_5300 : plusieurs modèles, axes dans la grille, au moins un axe temporel. | E26: 5300
... A30: test_csv_reader | B30: CsvFormatTests | C30: test_non_utf8_read_but_flagged_with_requirement | D30: REQ 2302 : un fichier Windows-1252 est une non-conformité (ERREUR, ligne citée), | E30: 2302
A31: test_csv_reader | B31: CsvFormatTests | C31: test_bom_tolerated_and_reported | E31: 2302
A32: test_csv_reader | B32: CsvFormatTests | C32: test_metadata_lines_reported_and_skipped | D32: REQ 2303 : préambule et lignes « # » signalés, données lues. | E32: 2303
A33: test_csv_reader | B33: CsvFormatTests | C33: test_header_names_normalized | D33: REQ 2309 : noms vides et doublons renommés et signalés. | E33: 2309
A34: test_csv_reader | B34: CsvFormatTests | C34: test_numeric_first_line_flagged | D34: REQ 2308 : une 1re ligne numérique n'est pas un en-tête. | E34: 2308
A35: test_csv_reader | B35: CsvFormatTests | C35: test_malformed_rows_rejected_without_blocking | E35: module : 2200, 2201, 2310, 4105
A36: test_csv_reader | B36: CsvFormatTests | C36: test_size_limit | D36: REQ 2310 : au-delà du maximum paramétré, le fichier est refusé. | E36: 2310
A37: test_csv_reader | B37: CsvFormatTests | C37: test_other_extension_warned | E37: 2300
A38: test_csv_reader | B38: CsvFormatTests | C38: test_empty_and_one_column_files | E38: module : 2200, 2201, 2310, 4105
A39: test_csv_reader | B39: CsvFormatTests | C39: test_cancellation | E39: 4105
A40: test_csv_reader | B40: CsvFormatTests | C40: test_large_file_progress | D40: REQ 4105 : lecture par blocs avec avancement. | E40: 4105
A41: test_csv_reader | B41: CsvFormatTests | C41: test_mixed_columns_converted_like_cell_by_cell | D41: REQ 4105 : colonnes mixtes converties par blocs avec le classement d'une cellule | E41: 4105
A42: test_csv_reader | B42: CsvFormatTests | C42: test_parse_numbers_isolates_bad_cells | D42: Conversion en bloc : les cellules refusées sont repérées une à une, les autres | E42: module : 2200, 2201, 2310, 4105
A43: test_csv_reader | B43: CsvFormatTests | C43: test_unreadable_file_isolated | D43: REQ 4105 / 2105 : un fichier malade est conservé avec son diagnostic. | E43: 2105, 4105
...
